Workbook

Sheet الملخص
A1: دراسة جدوى — مشروع 30 دجاجة بلدية + 3 سرادك (تونس)
A3: المؤشر | B3: القيمة | C3: ملاحظة
A4: إجمالي الاستثمار | B4: ='الاستثمار'!D14 | C4: عتاق + بناء + تجهيزات + احتياطي
A5: التكاليف التشغيلية س1 | B5: ='التشغيل'!B22 | C5: العلف ≈ 80% منها
A6: الإيراد النقدي س1 | B6: ='التشغيل'!B29 | C6: بيض + وضعيات + ديكارول
A7: الصافي النقدي س1 | B7: ='التشغيل'!B34 | C7: سنة تأسيس
A8: الصافي الاقتصادي س1 | B8: ='التشغيل'!B35 | C8: مع الاستهلاك الذاتي
A9: الصافي النقدي س2 | B9: ='التشغيل'!C34
A10: الصافي الاقتصادي س2 | B10: ='التشغيل'!C35
A11: مدة الاسترداد | B11: ='التشغيل'!B38 | C11: على الأساس الاقتصادي
A13: خلاصة الخبير
A14: 1) المشروع سليم اقتصادياً — دخل مكمّل في هذا الحجم، بمخاطرة منخفضة.
A15: 2) أعلى ربحية: كتاكيت ووضحيات في الربيع ورمضان؛ ديكارول عتاق قبل الأعياد (35–45 د.ت).
A16: 3) شرط النجاح: الخلط المنزلي (توفير ≈1800 د.ت/سنة) — الجاهز يكاد يُصفي الربح.
A17: 4) حدّث الأسعار من سوقك في ورقة الفرضيات.
A18: 5) أنفلونزا الطيور: أمن حيوي وإبلاغ فوري (CRDA/OVR) وسجّل القطيع للقاحات مدعمة.
A19: 6) التوسعة: فقاسة 50–100 بيضة بعد سنة لبيع كتاكيت عمر يوم.
A21: الخلايا الزرقاء قابلة للتعديل — كل الأرقام تتحدث تلقائياً.

Sheet الفرضيات
A1: الفرضيات — عدّل الخلايا الزرقاء فقط وستتحدث كل النتائج تلقائياً
A3: أسعار الشراء والبيع (استرشادية 2026 — تحقق منها في سوقك)
A4: سعر شراء الدجاجة العتاقة | B4: 30 | C4: د.ت | D4: المدى 25–40 د.ت (يرتفع في الربيع)
A5: سعر شراء السردوك العتاق | B5: 45 | C5: د.ت | D5: المدى 40–60 د.ت
A6: سعر بيع البيضة البلدية | B6: 0.6 | C6: د.ت | D6: 0.5–0.8 د.ت (ضعف التجاري)
A7: سعر بيع الوضحية (3–4 أشهر) | B7: 12 | C7: د.ت | D7: طلب مرتفع في الربيع ورمضان
A8: سعر بيع الديكرول (4–6 أشهر) | B8: 20 | C8: د.ت | D8: عتاق يُباع 35–45 قبل الأعياد
A9: سعر بيع المستصالحة | B9: 22 | C9: د.ت | D9: الدجاجة العجوز
A10: سعر علف البالغين | B10: 1.2 | C10: د.ت/كغ | D10: خلطة منزلية (انظر ورقة التغذية)
A11: سعر علف الفتيان | B11: 1.4 | C11: د.ت/كغ | D11: خلطة بادئ منزلية
A12: معطيات القطيع والإنتاج
A13: عدد الدجاج | B13: 30 | C13: دجاجة | D13: عنبر 8–10 م² + مشية 70–100 م²
A14: عدد السرادك | B14: 3 | C14: سردوك | D14: نسبة 1:10 للخصوبة
A15: نفوق البالغين سنوياً | B15: 0.05 | C15: % | D15: مع تحصينات وأمن حيوي
A16: إنتاج البيض/دجاجة/سنة | B16: 130 | C16: بيضة | D16: مدى واقعي 110–160
A17: نسبة البيض للتفريخ | B17: 0.1 | C17: % | D17: للفقس الطبيعي
A18: الاستهلاك الذاتي والهدايا | B18: 0.15 | C18: % | D18: قيمة للأسرة
A19: الكتاكيت الفاقسة سنوياً | B19: 80 | C19: كتكوت | D19: 3 دفعات فقس (ورقة الفقس)
A20: نفوق الكتاكيت حتى 8 أسابيع | B20: 0.15 | C20: % | D20: يخفض إلى 8% برعاية
A21: وضعيات مُبقاة للتجديد | B21: 10 | C21: وضحية
A22: وضحيات مبيعة سنوياً | B22: 30 | C22: وضحية
A23: مستصالحات مبيعة | B23: 5 | C23: دجاجة
A24: استهلاك البالغ من العلف | B24: 90 | C24: غ/يوم | D24: مع بقايا المائدة والرعي
A25: علف الفتيان السنوي | B25: 450 | C25: كغ
A26: صيدلة وتحصين | B26: 150 | C26: د.ت/سنة | D26: لقاحات OVR
A27: فرشة وطاقة ونثريات | B27: 100 | C27: د.ت/سنة
A28: احتياطي الطوارئ | B28: 0.1 | C28: % | D28: على المصاريف

Sheet الاستثمار
A1: التكاليف الاستثمارية لبدء المشروع (د.ت)
A3: البند | B3: الكمية | C3: سعر الوحدة | D3: الإجمالي
A4: دجاج بلدي عتاق (جاهز للبيض) | B4: 30 | C4: ='الفرضيات'!B4 | D4: =B4*C4
A5: سرادك عتاق | B5: 3 | C5: ='الفرضيات'!B5 | D5: =B5*C5
A6: بناء/تأهيل المذرك (10 م²) | B6: 1 | C6: 500 | D6: =B6*C6
A7: تسييج المشية | B7: 1 | C7: 300 | D7: =B7*C7
A8: أعشاش (8) + مجاثم | B8: 1 | C8: 130 | D8: =B8*C8
A9: معالف ومساقي (4+4) | B9: 1 | C9: 110 | D9: =B9*C9
A10: حظيرة الفراخ | B10: 1 | C10: 120 | D10: =B10*C10
A11: حوض رمل + أدوات + نقل | B11: 1 | C11: 110 | D11: =B11*C11
A12: المجموع | D12: =SUM(D4:D11)
A13: رأس مال احتياطي (شهرا علف) | B13: 1 | C13: 400 | D13: =B13*C13
A14: إجمالي الاستثمار المطلوب | D14: =D12+D13

Sheet التشغيل
A1: النموذج التشغيلي السنوي (د.ت)
A3: البند | B3: السنة 1 | C3: السنة 2 | D3: ملاحظات
A4: أولا: حسابات الإنتاج
A5: عدد الدجاج البالغ | B5: ='الفرضيات'!B13 | C5: =B5-'الفرضيات'!B23+'الفرضيات'!B21 | D5: س2: ناقص المستصالحات + التجديد
A6: عدد السرادك | B6: ='الفرضيات'!B14 | C6: =B6
A7: إنتاج البيض السنوي | B7: =B5*'الفرضيات'!B16 | C7: =C5*'الفرضيات'!B16 | D7: بيضة/دجاجة/سنة
A8: بيض التفريخ | B8: =B7*'الفرضيات'!B17 | C8: =C7*'الفرضيات'!B17
A9: استهلاك ذاتي وهدايا | B9: =B7*'الفرضيات'!B18 | C9: =C7*'الفرضيات'!B18
A10: البيض المعبوع للبيع | B10: =B7-B8-B9 | C10: =C7-C8-C9
A11: الكتاكيت الناجية | B11: ='الفرضيات'!B19*(1-'الفرضيات'!B20) | C11: =B11
A12: وضحيات مبيعة | B12: ='الفرضيات'!B22 | C12: =B12
A13: ديكارول مبيعة | B13: =B11-'الفرضيات'!B21-'الفرضيات'!B22 | C13: =C13
A14: مستصالحات مبيعة | B14: ='الفرضيات'!B23 | C14: =C5*2/10
A16: ثانيا: التكاليف التشغيلية السنوية
A17: علف البالغين | B17: =(B5+B6)*'الفرضيات'!B24/1000*365*'الفرضيات'!B10 | C17: =(C5+C6)*'الفرضيات'!B24/1000*365*'الفرضيات'!B10
A18: علف الفتيان | B18: ='الفرضيات'!B25*'الفرضيات'!B11 | C18: ='الفرضيات'!B25*'الفرضيات'!B11
A19: صيدلة وتحصين | B19: ='الفرضيات'!B26 | C19: ='الفرضيات'!B26
A20: فرشة وطاقة ونثريات | B20: ='الفرضيات'!B27 | C20: ='الفرضيات'!B27
A21: احتياطي الطوارئ | B21: =SUM(B17:B20)*'الفرضيات'!B28 | C21: =SUM(C17:C20)*'الفرضيات'!B28
A22: إجمالي التكاليف | B22: =SUM(B17:B21) | C22: =SUM(C17:C21)
A24: ثالثا: الإيرادات
A25: بيض بلدي | B25: =B10*'الفرضيات'!B6 | C25: =C10*'الفرضيات'!B6
A26: وضحيات | B26: =B12*'الفرضيات'!B7 | C26: =C12*'الفرضيات'!B7
A27: ديكارول | B27: =B13*'الفرضيات'!B8 | C27: =C13*'الفرضيات'!B8
A28: مستصالحات | B28: =B14*'الفرضيات'!B9 | C28: =C14*'الفرضيات'!B9
A29: إجمالي الإيراد النقدي | B29: =SUM(B25:B28) | C29: =SUM(C25:C28)
A30: قيمة الاستهلاك الذاتي | B30: =B9*'الفرضيات'!B6 | C30: =C9*'الفرضيات'!B6
A31: الإجمالي الاقتصادي | B31: =B29+B30 | C31: =C29+C30
A33: رابعا: النتيجة
A34: صافي الربح النقدي | B34: =B29-B22 | C34: =C29-C22
A35: صافي الربح الاقتصادي | B35: =B31-B22 | C35: =C31-C22
A37: خامسا: الاسترداد
A38: مدة الاسترداد (سنوات — اقتصادي) | B38: ='الاستثمار'!D14/AVERAGE(B35:C35) | D38: من الأرباح التراكمية

Sheet السيناريوهات
A1: تحليل السيناريوهات والحساسية — صافي السنة الأولى (د.ت)
A3: المعيار | B3: متشائم | C3: أساسي | D3: متفائل
A4: إنتاج البيض (بيضة/دجاجة) | B4: 110 | C4: 130 | D4: 160
A5: سعر البيضة (د.ت) | B5: 0.5 | C5: 0.6 | D5: 0.75
A6: الكتاكيت الفاقسة | B6: 60 | C6: 80 | D6: 100
A8: البيض الإجمالي | B8: =B4*30 | C8: =C4*30 | D8: =D4*30
A9: إيراد البيض + الاستهلاك الذاتي | B9: =B8*0.9*B5 | C9: =C8*0.9*C5 | D9: =D8*0.9*D5
A10: إيراد الوضعيات والديكارول والمستصالحات | B10: =360+(B6*0.85-40)*20+110 | C10: =360+(C6*0.85-40)*20+110 | D10: =360+(D6*0.85-40)*20+110
A11: التكاليف مع الطوارئ | B11: =(33*0.09*365*1.2+450*1.4+150+100)*1.1 | C11: =(33*0.09*365*1.2+450*1.4+150+100)*1.1 | D11: =(33*0.09*365*1.2+450*1.4+150+100)*1.1
A13: صافي الربح النقدي | B13: =B10-B11 | C13: =C10-C11 | D13: =D10-D11
A14: صافي الربح الاقتصادي | B14: =B9+B10-B11 | C14: =C9+C10-C11 | D14: =D9+D10-D11
A17: مصفوفة الحساسية: الصافي (د.ت) حسب سعر البيضة ↔ الإنتاج
A18: السعر \ الإنتاج | B18: 100 | C18: 115 | D18: 130 | E18: 145 | F18: 160
A19: 0.4 | B19: =30*100*0.9*0.4+1030-2400 | C19: =30*115*0.9*0.4+1030-2400 | D19: =30*130*0.9*0.4+1030-2400 | E19: =30*145*0.9*0.4+1030-2400 | F19: =30*160*0.9*0.4+1030-2400
A20: 0.5 | B20: =30*100*0.9*0.5+1030-2400 | C20: =30*115*0.9*0.5+1030-2400 | D20: =30*130*0.9*0.5+1030-2400 | E20: =30*145*0.9*0.5+1030-2400 | F20: =30*160*0.9*0.5+1030-2400
A21: 0.6 | B21: =30*100*0.9*0.6+1030-2400 | C21: =30*115*0.9*0.6+1030-2400 | D21: =30*130*0.9*0.6+1030-2400 | E21: =30*145*0.9*0.6+1030-2400 | F21: =30*160*0.9*0.6+1030-2400
A22: 0.7 | B22: =30*100*0.9*0.7+1030-2400 | C22: =30*115*0.9*0.7+1030-2400 | D22: =30*130*0.9*0.7+1030-2400 | E22: =30*145*0.9*0.7+1030-2400 | F22: =30*160*0.9*0.7+1030-2400
A23: 0.8 | B23: =30*100*0.9*0.8+1030-2400 | C23: =30*115*0.9*0.8+1030-2400 | D23: =30*130*0.9*0.8+1030-2400 | E23: =30*145*0.9*0.8+1030-2400 | F23: =30*160*0.9*0.8+1030-2400
A25: (75% بيع + 15% استهلاك ذاتي) — إيراد ثابت آخر 1030 وتكاليف 2400

Sheet الصحة
A1: التقويم الصحي والفلاحي (شروط تونس)
A3: الفترة | B3: العملية | C3: التفاصيل
A4: أوت–سبتمبر | B4: مقاومة الحرارة | C4: تظليل، ماء بارد متجدد، فيتامين C/إلكتروليت؛ البيض يهبط 20–30% طبيعياً
A5: سبتمبر–أكتوبر | B5: الديدان والطفيليات | C5: مضاد ديدان + رش المذرك + قمل وحلم
A6: أكتوبر–نوفمبر | B6: نيوكاسل + جدري | C6: تيلون/لسوتا بالشرب؛ الجدري قبل الناموس؛ لقاحات OVR
A7: نوفمبر–جانفي | B7: الإدارة الشتوية | C7: إضاءة 14 ساعة (اختياري)؛ فرشة سميكة؛ حماية من الرياح
A8: فيفري–مارس | B8: ذروة البيض | C8: نيوكاسل منشط؛ كالسيوم (قواقع)؛ تحضير عشون الفقس
A9: مارس–جوان | B9: موسم الفقس | C9: عزل الراقدة (10–12 بيضة، 21 يوماً)؛ علف بادئ للفراخ؛ 2–3 دورات
A10: طوال السنة | B10: الأمن الحيوي | C10: حجر صحي 2–3 أسابيع؛ رمل+رماد؛ قوارض؛ منع الطيور البرية
A11: طوال السنة | B11: الإنذار البيطري | C11: نفوق جماعي → إبلاغ فوري CRDA (احتراس أنفلونزا الطيور)
A14: برنامج الفراخ (0–8 أسابيع)
A15: يوم 1–7 | B15: حرارة 32–35°م، ماء بفيتامينات، بادئ 19–20% بروتين
A16: يوم 7 | B16: نيوكاسل HD
A17: يوم 12–18 | B17: جمبورو
A18: يوم 21–28 | B18: جمبورو + لسوتا
A19: باستمرار | B19: فرشة جافة (كوكسيديا)؛ −3°/أسبوع حتى 21°

Sheet الفني
A1: المواصفات الفنية للحظيرة (33 طائراً)
A3: العنصر | B3: المقاس | C3: للمشروع
A4: المذرك المغلق | B4: 0.25–0.30 م²/طائر | C4: 8–10 م² (4×2.5م)
A5: ساحة المشية | B5: 2–3 م²/طائر | C5: 70–100 م² مسيّجة
A6: الأعشاش | B6: 1 لكل 4 دجاجات | C6: 7–8 أعشاش 35×35×35 سم
A7: المجاثم | B7: 20–25 سم/طائر | C7: ≈7 م، ارتفاع 60–90 سم
A8: المعالف | B8: 10–12 سم/طائر | C8: 4 معالف
A9: المساقي | B9: 1.5–2 سم/طائر | C9: 4 مساقي
A10: حوض الرمل | B10: 60×40 سم | C10: رمل + رماد خشب
A11: التوجيه | B11: شرق–غرب | C11: مصد شمالي، سقف مائل
A12: الفرشة | B12: 10–15 سم | C12: قش/نشارة، تجديد كل 6–8 أسابيع
A13: حرارة الفراخ | B13: 32–35°م يوم 1 | C13: −3°/أسبوع حتى 21°
A14: الإضاءة | B14: 14 ساعة للبياض | C14: LED شتاءً (اختياري)
A15: الماء | B15: دائم | C15: 6–8 ل/يوم، ×2 صيفاً

Sheet الفقس
A1: جدول الفقس الطبيعي الموسمي — ≈ 80 كتكوت/سنة
A3: أولا: علامات الجعال والتحضير
A4: علامات الجعال | B4: تبيت في العش، تنفش، تنقر عند اللمس، ترفض الخروج — فيفري إلى جوان
A5: صندوق الجعال | B5: منفصل معتم 40×40×40 سم، فرشة قش محفوّرة، ماء وعلف على الباب
A6: بيض التفريخ | B6: طازج ≤7 أيام، متوسط الحجم، 14–18° بوضع مائل — لا يُغسل
A7: قاعدة ذهبية | B7: لا تغيّر مكان الراقدة ولا تعالجها أثناء الرقاد
A9: ثانيا: الأحضان الثلاثة
A10: الدفعة | B10: وضع البيض | C10: التقنين | D10: الفقس | E10: ملاحظات
A11: دفعة 1 (3×11 بيضة) | B11: منتصف مارس | C11: +7 | D11: 5 أفريل | E11: ≈24 كتكوت — فطام 1 جوان
A12: دفعة 2 | B12: 5 أفريل | C12: 12 أفريل | D12: 26 أفريل | E12: ≈24 — فطام 22 جوان
A13: دفعة 3 | B13: 25 أفريل | C13: 2 ماي | D13: 16 ماي | E13: ≈24 — فطام 10 جويلية
A14: المجموع | B14: 99 بيضة | D14: ≈75–80 كتكوت | E14: يطابق فرضية الدراسة
A16: ثالثا: الخط الزمني
A17: يوم 0 | B17: 10–12 بيضة مساءً بعلامة قلم رصاص
A18: يوم 7 | B18: تقنين بالشمعة: أوردة حمراء = مخصب
A19: يوم 19–21 | B19: الفقس دون إزعاج
A20: +24–48 س | B20: نقل الكتاكيت مع الأم لصندوق الفراخ
A21: أسبوع 1–8 | B21: بادئ 20% بروتين؛ فارس أول أسبوعين؛ برّة من الأسبوع 4
A22: أسبوع 8 | B22: الفطام وفرز الذكور (ديكارول/وضحيات)
A24: رابعا: إدارة الجعّالات
A25: عدد الفقسات | B25: 2–3 في الموسم كافية
A26: كسر الجعال | B26: قفص مضيء مهوّى 3–4 أيام
A27: الفصل | B27: الصندوق بعيد عن القطيع
A28: السجل | B28: تاريخ وبيض وفاقس ونفوق لكل فقسة

Sheet التغذية
A1: خطة التغذية المختلطة — خلط منزلي
A3: أولا: أسعار المواد الخام (د.ت/كغ)
A4: شعير | B4: 0.9 | C4: د.ت/كغ | D4: سوق/فلاح
A5: ذرة صفراء (الديوان) | B5: 0.87 | C5: د.ت/كغ | D5: 866 د.ت/طن أوت 2026
A6: نخالة قمح | B6: 0.6 | C6: د.ت/كغ | D6: المطاحن
A7: كسب صويا 46% | B7: 2 | C7: د.ت/كغ | D7: مصانع الأعلاف بالكيلو
A8: قواقع/أصداف | B8: 0.9 | C8: د.ت/كغ | D8: كالسيوم
A9: بريمكس دواجن | B9: 40 | C9: د.ت/كغ | D9: نصف كغ لكل 100 كغ
A10: ملح | B10: 0.5 | C10: د.ت/كغ
A11: علف واضع جاهز | B11: 2.4 | C11: د.ت/كغ | D11: للمقارنة
A12: بادئ جاهز | B12: 2.6 | C12: د.ت/كغ | D12: للمقارنة
A13: ثانيا: خلطة الواضعين — بروتين ≈14–15%
A14: المادة | B14: كغ/100كغ | C14: سعر الكيلو | D14: التكلفة (د.ت) | E14: البروتين %
A15: شعير | B15: 40 | C15: =$B$4 | D15: =B15*C15/100 | E15: =0.09*B15
A16: ذرة صفراء | B16: 30 | C16: =$B$5 | D16: =B16*C16/100 | E16: =0.08*B16
A17: نخالة | B17: 10 | C17: =$B$6 | D17: =B17*C17/100 | E17: =0.15*B17
A18: كسب صويا | B18: 15 | C18: =$B$7 | D18: =B18*C18/100 | E18: =0.46*B18
A19: قواقع | B19: 4 | C19: =$B$8 | D19: =B19*C19/100 | E19: =0.0*B19
A20: بريمكس | B20: 0.5 | C20: =$B$9 | D20: =B20*C20/100 | E20: =0.0*B20
A21: ملح | B21: 0.5 | C21: =$B$10 | D21: =B21*C21/100 | E21: =0.0*B21
A22: المجموع | B22: =SUM(B15:B21) | D22: =SUM(D15:D21) | E22: =SUM(E15:E21)
A23: كلفة كيلو الخلطة | B23: =D22 | D23: اسحق أو اشترِ مجروشاً
A24: نفس الكيلو جاهزاً | B24: =$B$11 | D24: علف مركب تجاري
A25: التوفير لكل كيلو | B25: =B24-B23 | D25: ≈1.18 د.ت أرخص (49%)
A26: التوفير السنوي (د.ت) | B26: =B25*365*33*0.09 | D26: مقابل الواضع الجاهز
A28: ثالثا: خلطة الفتيان 0–8 أسابيع — بروتين ≈20–21%
A29: المادة | B29: كغ/100كغ | C29: سعر الكيلو | D29: التكلفة (د.ت) | E29: البروتين %
A30: ذرة صفراء | B30: 38 | C30: =$B$5 | D30: =B30*C30/100 | E30: =0.08*B30
A31: شعير | B31: 18 | C31: =$B$4 | D31: =B31*C31/100 | E31: =0.09*B31
A32: كسب صويا | B32: 32 | C32: =$B$7 | D32: =B32*C32/100 | E32: =0.46*B32
A33: نخالة | B33: 9.7 | C33: =$B$6 | D33: =B33*C33/100 | E33: =0.15*B33
A34: قواقع | B34: 1.5 | C34: =$B$8 | D34: =B34*C34/100 | E34: =0.0*B34
A35: بريمكس | B35: 0.5 | C35: =$B$9 | D35: =B35*C35/100 | E35: =0.0*B35
A36: ملح | B36: 0.3 | C36: =$B$10 | D36: =B36*C36/100 | E36: =0.0*B36
A37: المجموع | B37: =SUM(B30:B36) | D37: =SUM(D30:D36) | E37: =SUM(E30:E36)
A38: كلفة كيلو الخلطة | B38: =D37 | D38: من الأسبوع 6: صويا 25% (كسر)
A39: نفس الكيلو جاهزاً | B39: =$B$12 | D39: علف مركب تجاري
A40: التوفير لكل كيلو | B40: =B39-B38 | D40: ≈1.19 د.ت أرخص (46%)
A41: التوفير السنوي على 450 كغ (د.ت) | B41: =B40*450 | D41: مقابل البادئ الجاهز
A43: رابعا: القواعد اليومية
...
